<?xml version="1.0" encoding="utf-8"?>
<!-- This URDF was automatically created by SolidWorks to URDF Exporter! Originally created by Stephen Brawner (brawner@gmail.com) 
     Commit Version: 1.6.0-4-g7f85cfe  Build Version: 1.6.7995.38578
     For more information, please see http://wiki.ros.org/sw_urdf_exporter -->
<robot
  name="Infantry2023">
<link name="base_footprint">
    <visual>
        <origin xyz="0 0 0" rpy="0 0 0" />
        <geometry>
            <box size="0.001 0.001 0.001" />
        </geometry>
    </visual>
</link>

<joint name="base_footprint_joint" type="fixed">
    <origin xyz="0 0 0.001" rpy="0 0 0" />
    <parent link="base_footprint"/>
    <child link="base_link" />
</joint>
  <link
    name="base_link">
    <inertial>
      <origin
        xyz="-4.44731268389602E-05 -0.0128958761443199 0.0452136078609108"
        rpy="0 0 0" />
      <mass
        value="3.32445638874452" />
      <inertia
        ixx="0.00491568530747167"
        ixy="3.12661948325221E-07"
        ixz="6.0478132968072E-06"
        iyy="0.00558523884351327"
        iyz="-2.72827472437847E-05"
        izz="0.00788013913942305" />
    </inertial>
    <visual>
      <origin
        xyz="0 0 0"
        rpy="0 0 0" />
      <geometry>
        <mesh
          filename="package://infantry2023_description/meshes/visual/base_link.STL" />
      </geometry>
      <material
        name="">
        <color
          rgba="0.627450980392157 0.627450980392157 0.627450980392157 1" />
      </material>
    </visual>
    <collision>
      <origin
        xyz="0 0 0"
        rpy="0 0 0" />
      <geometry>
        <mesh
          filename="package://infantry2023_description/meshes/visual/base_link.STL" />
      </geometry>
    </collision>
  </link>
  <link
    name="Swerve1">
    <inertial>
      <origin
        xyz="-0.00218228603039089 -0.00561838251563398 0.000154985992435519"
        rpy="0 0 0" />
      <mass
        value="0.12509051804459" />
      <inertia
        ixx="0.000116981505902208"
        ixy="-1.18216858539901E-06"
        ixz="7.48448129109755E-09"
        iyy="8.01262501702026E-05"
        iyz="1.76996404557449E-06"
        izz="6.59357695156801E-05" />
    </inertial>
    <visual>
      <origin
        xyz="0 0 0"
        rpy="0 0 0" />
      <geometry>
        <mesh
          filename="package://infantry2023_description/meshes/visual/Swerve1.STL" />
      </geometry>
      <material
        name="">
        <color
          rgba="0.792156862745098 0.819607843137255 0.933333333333333 1" />
      </material>
    </visual>
    <collision>
      <origin
        xyz="0 0 0"
        rpy="0 0 0" />
      <geometry>
        <mesh
          filename="package://infantry2023_description/meshes/visual/Swerve1.STL" />
      </geometry>
    </collision>
  </link>
  <joint
    name="SwerveOrt1"
    type="continuous">
    <origin
      xyz="0.117999999999998 -0.118 0"
      rpy="1.5707963267949 0 -1.0077804964065" />
    <parent
      link="base_link" />
    <child
      link="Swerve1" />
    <axis
      xyz="0 1 0" />
  </joint>
  <link
    name="Wheel1">
    <inertial>
      <origin
        xyz="-0.00181927157167486 3.36064289868654E-08 2.74504813879695E-08"
        rpy="0 0 0" />
      <mass
        value="0.0781527646115954" />
      <inertia
        ixx="0.000152722323872376"
        ixy="1.12277614929581E-11"
        ixz="9.56457614627001E-12"
        iyy="8.06084271810555E-05"
        iyz="1.18378410380445E-10"
        izz="8.06079297167232E-05" />
    </inertial>
    <visual>
      <origin
        xyz="0 0 0"
        rpy="0 0 0" />
      <geometry>
        <mesh
          filename="package://infantry2023_description/meshes/visual/Wheel1.STL" />
      </geometry>
      <material
        name="">
        <color
          rgba="0.792156862745098 0.819607843137255 0.933333333333333 1" />
      </material>
    </visual>
    <collision>
      <origin
        xyz="0 0 0"
        rpy="0 0 0" />
      <geometry>
        <mesh
          filename="package://infantry2023_description/meshes/visual/Wheel1.STL" />
      </geometry>
    </collision>
  </link>
  <joint
    name="Wheel1"
    type="continuous">
    <origin
      xyz="0 -0.0207999999999906 9.02643274049153E-05"
      rpy="-0.584542615061481 0 0" />
    <parent
      link="Swerve1" />
    <child
      link="Wheel1" />
    <axis
      xyz="1 0 0" />
  </joint>
  <link
    name="Swerve2">
    <inertial>
      <origin
        xyz="-0.00165675945646224 -0.00561838267415753 -0.00142882729081312"
        rpy="0 0 0" />
      <mass
        value="0.125090525969345" />
      <inertia
        ixx="9.15958729998234E-05"
        ixy="-2.08628605932632E-06"
        ixz="2.55225001901956E-05"
        iyy="8.01262508302358E-05"
        iyz="4.21550708362048E-07"
        izz="9.1321403934597E-05" />
    </inertial>
    <visual>
      <origin
        xyz="0 0 0"
        rpy="0 0 0" />
      <geometry>
        <mesh
          filename="package://infantry2023_description/meshes/visual/Swerve2.STL" />
      </geometry>
      <material
        name="">
        <color
          rgba="0.792156862745098 0.819607843137255 0.933333333333333 1" />
      </material>
    </visual>
    <collision>
      <origin
        xyz="0 0 0"
        rpy="0 0 0" />
      <geometry>
        <mesh
          filename="package://infantry2023_description/meshes/visual/Swerve2.STL" />
      </geometry>
    </collision>
  </link>
  <joint
    name="SwerveOrt2"
    type="continuous">
    <origin
      xyz="-0.117999999999998 -0.118000000000005 0"
      rpy="1.5707963267949 0 0.0452748853481586" />
    <parent
      link="base_link" />
    <child
      link="Swerve2" />
    <axis
      xyz="0 1 0" />
  </joint>
  <link
    name="Wheel2">
    <inertial>
      <origin
        xyz="-0.00181927157167293 3.36064223255272E-08 2.74504762809435E-08"
        rpy="0 0 0" />
      <mass
        value="0.0781527646115949" />
      <inertia
        ixx="0.000152722323872376"
        ixy="1.12277614353599E-11"
        ixz="9.56457623266737E-12"
        iyy="8.0608427181056E-05"
        iyz="1.18378410342328E-10"
        izz="8.06079297167238E-05" />
    </inertial>
    <visual>
      <origin
        xyz="0 0 0"
        rpy="0 0 0" />
      <geometry>
        <mesh
          filename="package://infantry2023_description/meshes/visual/Wheel2.STL" />
      </geometry>
      <material
        name="">
        <color
          rgba="0.792156862745098 0.819607843137255 0.933333333333333 1" />
      </material>
    </visual>
    <collision>
      <origin
        xyz="0 0 0"
        rpy="0 0 0" />
      <geometry>
        <mesh
          filename="package://infantry2023_description/meshes/visual/Wheel2.STL" />
      </geometry>
    </collision>
  </link>
  <joint
    name="Wheel2"
    type="continuous">
    <origin
      xyz="-6.36453073919047E-05 -0.0208000000000706 6.40072156073007E-05"
      rpy="-0.584542615061623 -0.782563066705172 0" />
    <parent
      link="Swerve2" />
    <child
      link="Wheel2" />
    <axis
      xyz="1 0 0" />
  </joint>
  <link
    name="Swerve3">
    <inertial>
      <origin
        xyz="-0.00165474205243812 -0.00561927055977862 -0.00143085388976742"
        rpy="0 0 0" />
      <mass
        value="0.125090517964765" />
      <inertia
        ixx="9.15949389868014E-05"
        ixy="-2.08309795519893E-06"
        ixz="2.55248553899142E-05"
        iyy="8.01309763200056E-05"
        iyz="4.15667291107872E-07"
        izz="9.13176103696124E-05" />
    </inertial>
    <visual>
      <origin
        xyz="0 0 0"
        rpy="0 0 0" />
      <geometry>
        <mesh
          filename="package://infantry2023_description/meshes/visual/Swerve3.STL" />
      </geometry>
      <material
        name="">
        <color
          rgba="0.792156862745098 0.819607843137255 0.933333333333333 1" />
      </material>
    </visual>
    <collision>
      <origin
        xyz="0 0 0"
        rpy="0 0 0" />
      <geometry>
        <mesh
          filename="package://infantry2023_description/meshes/visual/Swerve3.STL" />
      </geometry>
    </collision>
  </link>
  <joint
    name="SwerveOrt3"
    type="continuous">
    <origin
      xyz="-0.118000000000001 0.117999999999997 0"
      rpy="1.5707963267949 0 2.82650685286413" />
    <parent
      link="base_link" />
    <child
      link="Swerve3" />
    <axis
      xyz="0 1 0" />
  </joint>
  <link
    name="Wheel3">
    <inertial>
      <origin
        xyz="-0.00181927277030913 7.13123274320715E-09 3.44955778525113E-09"
        rpy="0 0 0" />
      <mass
        value="0.0781527846492034" />
      <inertia
        ixx="0.000152722241044495"
        ixy="3.85994347921158E-12"
        ixz="2.88532717344719E-12"
        iyy="8.06082280952508E-05"
        iyz="8.97427221070886E-12"
        izz="8.06080464826168E-05" />
    </inertial>
    <visual>
      <origin
        xyz="0 0 0"
        rpy="0 0 0" />
      <geometry>
        <mesh
          filename="package://infantry2023_description/meshes/visual/Wheel3.STL" />
      </geometry>
      <material
        name="">
        <color
          rgba="0.792156862745098 0.819607843137255 0.933333333333333 1" />
      </material>
    </visual>
    <collision>
      <origin
        xyz="0 0 0"
        rpy="0 0 0" />
      <geometry>
        <mesh
          filename="package://infantry2023_description/meshes/visual/Wheel3.STL" />
      </geometry>
    </collision>
  </link>
  <joint
    name="Wheel3"
    type="continuous">
    <origin
      xyz="-6.36453073868948E-05 -0.0207999999999939 6.40072156022353E-05"
      rpy="-2.28570134033651 -0.782563066705175 0" />
    <parent
      link="Swerve3" />
    <child
      link="Wheel3" />
    <axis
      xyz="1 0 0" />
  </joint>
  <link
    name="Swerve4">
    <inertial>
      <origin
        xyz="-0.00165676146400878 -0.0056183827508177 -0.00142882907128244"
        rpy="0 0 0" />
      <mass
        value="0.125090533339578" />
      <inertia
        ixx="9.15958737370791E-05"
        ixy="-2.08628549049005E-06"
        ixz="2.55225000199367E-05"
        iyy="8.01262510701868E-05"
        iyz="4.21550053342676E-07"
        izz="9.1321404723039E-05" />
    </inertial>
    <visual>
      <origin
        xyz="0 0 0"
        rpy="0 0 0" />
      <geometry>
        <mesh
          filename="package://infantry2023_description/meshes/visual/Swerve4.STL" />
      </geometry>
      <material
        name="">
        <color
          rgba="0.792156862745098 0.819607843137255 0.933333333333333 1" />
      </material>
    </visual>
    <collision>
      <origin
        xyz="0 0 0"
        rpy="0 0 0" />
      <geometry>
        <mesh
          filename="package://infantry2023_description/meshes/visual/Swerve4.STL" />
      </geometry>
    </collision>
  </link>
  <joint
    name="SwerveOrt4"
    type="continuous">
    <origin
      xyz="0.117999999999991 0.117999999999998 0"
      rpy="1.5707963267949 0 0.454955024862355" />
    <parent
      link="base_link" />
    <child
      link="Swerve4" />
    <axis
      xyz="0 1 0" />
  </joint>
  <link
    name="Wheel4">
    <inertial>
      <origin
        xyz="-0.00181927157167497 3.3606435620448E-08 2.74504864672398E-08"
        rpy="0 0 0" />
      <mass
        value="0.0781527646115949" />
      <inertia
        ixx="0.000152722323872377"
        ixy="1.12277615802025E-11"
        ixz="9.56457621572671E-12"
        iyy="8.0608427181056E-05"
        iyz="1.18378410745516E-10"
        izz="8.06079297167232E-05" />
    </inertial>
    <visual>
      <origin
        xyz="0 0 0"
        rpy="0 0 0" />
      <geometry>
        <mesh
          filename="package://infantry2023_description/meshes/visual/Wheel4.STL" />
      </geometry>
      <material
        name="">
        <color
          rgba="0.792156862745098 0.819607843137255 0.933333333333333 1" />
      </material>
    </visual>
    <collision>
      <origin
        xyz="0 0 0"
        rpy="0 0 0" />
      <geometry>
        <mesh
          filename="package://infantry2023_description/meshes/visual/Wheel4.STL" />
      </geometry>
    </collision>
  </link>
  <joint
    name="Wheel4"
    type="continuous">
    <origin
      xyz="-6.36453073884491E-05 -0.0207999999998955 6.40072156038243E-05"
      rpy="-0.584542615061526 -0.782563066705173 0" />
    <parent
      link="Swerve4" />
    <child
      link="Wheel4" />
    <axis
      xyz="1 0 0" />
  </joint>
  <link
    name="TurretBody">
    <inertial>
      <origin
        xyz="-0.00238952849570441 0.058759051673963 0.0124010780918334"
        rpy="0 0 0" />
      <mass
        value="0.622229722588355" />
      <inertia
        ixx="0.000646381393997478"
        ixy="-5.93749252738385E-06"
        ixz="-1.1270166357088E-05"
        iyy="0.000465990637412568"
        iyz="6.89675151459739E-06"
        izz="0.000624308726742422" />
    </inertial>
    <visual>
      <origin
        xyz="0 0 0"
        rpy="0 0 0" />
      <geometry>
        <mesh
          filename="package://infantry2023_description/meshes/visual/TurretBody.STL" />
      </geometry>
      <material
        name="">
        <color
          rgba="0.792156862745098 0.819607843137255 0.933333333333333 1" />
      </material>
    </visual>
    <collision>
      <origin
        xyz="0 0 0"
        rpy="0 0 0" />
      <geometry>
        <mesh
          filename="package://infantry2023_description/meshes/visual/TurretBody.STL" />
      </geometry>
    </collision>
  </link>
  <joint
    name="TurretOrt"
    type="continuous">
    <origin
      xyz="0 0 0.104999999999996"
      rpy="1.57079632679489 0 -2.79982925994276" />
    <parent
      link="base_link" />
    <child
      link="TurretBody" />
    <axis
      xyz="0 1 0" />
  </joint>
  <link
    name="Gun">
    <inertial>
      <origin
        xyz="0.000605233842979931 0.0310866824300715 0.0843430608790675"
        rpy="0 0 0" />
      <mass
        value="0.527530322363297" />
      <inertia
        ixx="0.000430548962224304"
        ixy="2.28755576937329E-07"
        ixz="-9.46127412290321E-07"
        iyy="0.000517544568671493"
        iyz="-9.43790260156085E-06"
        izz="0.000224765295838933" />
    </inertial>
    <visual>
      <origin
        xyz="0 0 0"
        rpy="0 0 0" />
      <geometry>
        <mesh
          filename="package://infantry2023_description/meshes/visual/Gun.STL" />
      </geometry>
      <material
        name="">
        <color
          rgba="0.752941176470588 0.752941176470588 0.752941176470588 1" />
      </material>
    </visual>
    <collision>
      <origin
        xyz="0 0 0"
        rpy="0 0 0" />
      <geometry>
        <mesh
          filename="package://infantry2023_description/meshes/visual/Gun.STL" />
      </geometry>
    </collision>
  </link>
  <joint
    name="GunRevo"
    type="continuous">
    <origin
      xyz="0 0.1625 0"
      rpy="-0.446108315328483 0 0" />
    <parent
      link="TurretBody" />
    <child
      link="Gun" />
    <axis
      xyz="1 0 0" />
  </joint>
</robot>